/home/zihan/anaconda3/envs/x/lib/python3.7/site-packages/tensorflow/python/framework/dtypes.py:516: FutureWarning: Passing (type, 1) or '1type' as a synonym of type is deprecated; in a future version of numpy, it will be understood as (type, (1,)) / '(1,)type'.
  _np_qint8 = np.dtype([("qint8", np.int8, 1)])
/home/zihan/anaconda3/envs/x/lib/python3.7/site-packages/tensorflow/python/framework/dtypes.py:517: FutureWarning: Passing (type, 1) or '1type' as a synonym of type is deprecated; in a future version of numpy, it will be understood as (type, (1,)) / '(1,)type'.
  _np_quint8 = np.dtype([("quint8", np.uint8, 1)])
/home/zihan/anaconda3/envs/x/lib/python3.7/site-packages/tensorflow/python/framework/dtypes.py:518: FutureWarning: Passing (type, 1) or '1type' as a synonym of type is deprecated; in a future version of numpy, it will be understood as (type, (1,)) / '(1,)type'.
  _np_qint16 = np.dtype([("qint16", np.int16, 1)])
/home/zihan/anaconda3/envs/x/lib/python3.7/site-packages/tensorflow/python/framework/dtypes.py:519: FutureWarning: Passing (type, 1) or '1type' as a synonym of type is deprecated; in a future version of numpy, it will be understood as (type, (1,)) / '(1,)type'.
  _np_quint16 = np.dtype([("quint16", np.uint16, 1)])
/home/zihan/anaconda3/envs/x/lib/python3.7/site-packages/tensorflow/python/framework/dtypes.py:520: FutureWarning: Passing (type, 1) or '1type' as a synonym of type is deprecated; in a future version of numpy, it will be understood as (type, (1,)) / '(1,)type'.
  _np_qint32 = np.dtype([("qint32", np.int32, 1)])
/home/zihan/anaconda3/envs/x/lib/python3.7/site-packages/tensorflow/python/framework/dtypes.py:525: FutureWarning: Passing (type, 1) or '1type' as a synonym of type is deprecated; in a future version of numpy, it will be understood as (type, (1,)) / '(1,)type'.
  np_resource = np.dtype([("resource", np.ubyte, 1)])
Process Process-3:
Traceback (most recent call last):
  File "/home/zihan/anaconda3/envs/x/lib/python3.7/multiprocessing/process.py", line 297, in _bootstrap
    self.run()
  File "/home/zihan/anaconda3/envs/x/lib/python3.7/multiprocessing/process.py", line 99, in run
    self._target(*self._args, **self._kwargs)
  File "/home/zihan/research/marl_torch/utils/env.py", line 509, in _worker
    cmd, data = p.recv()
  File "/home/zihan/anaconda3/envs/x/lib/python3.7/multiprocessing/connection.py", line 250, in recv
    buf = self._recv_bytes()
  File "/home/zihan/anaconda3/envs/x/lib/python3.7/multiprocessing/connection.py", line 407, in _recv_bytes
    buf = self._recv(4)
  File "/home/zihan/anaconda3/envs/x/lib/python3.7/multiprocessing/connection.py", line 379, in _recv
    chunk = read(handle, remaining)
ConnectionResetError: [Errno 104] Connection reset by peer
Process Process-2:
Traceback (most recent call last):
  File "/home/zihan/anaconda3/envs/x/lib/python3.7/multiprocessing/process.py", line 297, in _bootstrap
    self.run()
  File "/home/zihan/anaconda3/envs/x/lib/python3.7/multiprocessing/process.py", line 99, in run
    self._target(*self._args, **self._kwargs)
  File "/home/zihan/research/marl_torch/utils/env.py", line 509, in _worker
    cmd, data = p.recv()
  File "/home/zihan/anaconda3/envs/x/lib/python3.7/multiprocessing/connection.py", line 250, in recv
    buf = self._recv_bytes()
  File "/home/zihan/anaconda3/envs/x/lib/python3.7/multiprocessing/connection.py", line 407, in _recv_bytes
    buf = self._recv(4)
  File "/home/zihan/anaconda3/envs/x/lib/python3.7/multiprocessing/connection.py", line 379, in _recv
    chunk = read(handle, remaining)
ConnectionResetError: [Errno 104] Connection reset by peer
Process Process-1:
Traceback (most recent call last):
  File "/home/zihan/anaconda3/envs/x/lib/python3.7/multiprocessing/process.py", line 297, in _bootstrap
    self.run()
  File "/home/zihan/anaconda3/envs/x/lib/python3.7/multiprocessing/process.py", line 99, in run
    self._target(*self._args, **self._kwargs)
  File "/home/zihan/research/marl_torch/utils/env.py", line 509, in _worker
    cmd, data = p.recv()
  File "/home/zihan/anaconda3/envs/x/lib/python3.7/multiprocessing/connection.py", line 250, in recv
    buf = self._recv_bytes()
  File "/home/zihan/anaconda3/envs/x/lib/python3.7/multiprocessing/connection.py", line 407, in _recv_bytes
    buf = self._recv(4)
  File "/home/zihan/anaconda3/envs/x/lib/python3.7/multiprocessing/connection.py", line 379, in _recv
    chunk = read(handle, remaining)
ConnectionResetError: [Errno 104] Connection reset by peer
